Workbook

Sheet E vs K
E2: 0.1 | N2: Datos Matlab 0.1
B3: E | C3: k | E3: E | F3: k | N3: E | O3: k
B4: 10 | C4: 1.4008761 | E4: 10 | F4: 1.4007382 | N4: 10000000 | O4: 1.4007382
B5: 40 | C5: 1.2140668 | E5: 40 | F5: 1.2140668 | N5: 40000000 | O5: 1.2140668
B6: 100 | C6: 1.1364515 | E6: 100 | F6: 1.1177048 | N6: 100000000 | O6: 1.1177048
B7: 200 | C7: 1.1021356 | E7: 200 | F7: 1.0909214 | N7: 200000000 | O7: 1.0909214
B8: 300 | C8: 1.0895844 | E8: 300 | F8: 1.0805844 | N8: 300000000 | O8: 1.0805844
B9: 500 | C9: 1.0619149 | E9: 500 | F9: 1.0723113 | N9: 500000000 | O9: 1.0723113
E10: 700 | F10: 1.0694335 | N10: 700000000 | O10: 1.0694335
E11: 1000 | F11: 1.0629208 | N11: 1000000000 | O11: 1.0629208
B12: E | C12: k
B13: 10 | C13: 1.3259737 | E13: 0.3 | N13: Datos Matlab 0.3
B14: 40 | C14: 1.1531018 | E14: E | F14: k | N14: E | O14: k
B15: 100 | C15: 1.0971813 | E15: 10 | F15: 1.3259737 | N15: 10000000 | O15: 1.3259737
B16: 200 | C16: 1.0655489 | E16: 40 | F16: 1.1531018 | N16: 40000000 | O16: 1.1531018
B17: 300 | C17: 1.048483 | E17: 100 | F17: 1.0821813 | N17: 100000000 | O17: 1.0821813
B18: 500 | C18: 1.0242472 | E18: 200 | F18: 1.0539489 | N18: 200000000 | O18: 1.0539489
E19: 300 | F19: 1.043483 | N19: 300000000 | O19: 1.043483
E20: 500 | F20: 1.0350256 | N20: 500000000 | O20: 1.0350256
B21: E | C21: k | E21: 700 | F21: 1.0306194 | N21: 700000000 | O21: 1.0306194
B22: 10 | C22: 1.2535679 | E22: 1000 | F22: 1.0245285 | N22: 1000000000 | O22: 1.0245285
B23: 40 | C23: 1.097158
B24: 100 | C24: 1.044067 | E24: 0.495 | N24: Datos Matlab 0.5
B25: 200 | C25: 1.0178564 | E25: E | F25: k | N25: E | O25: k
B26: 300 | C26: 1.0079754 | E26: 10 | F26: 1.2535679 | N26: 10000000 | O26: 1.2535679
B27: 500 | C27: 0.98769793 | E27: 40 | F27: 1.097158 | N27: 40000000 | O27: 1.097158
E28: 100 | F28: 1.040067 | N28: 100000000 | O28: 1.040067
E29: 200 | F29: 1.0169791 | N29: 200000000 | O29: 1.0169791
E30: 300 | F30: 1.0094218 | N30: 300000000 | O30: 1.0094218
E31: 500 | F31: 0.9977603 | N31: 500000000 | O31: 0.9977603
E32: 700 | F32: 0.98765619 | N32: 700000000 | O32: 0.98765619
E33: 1000 | F33: 0.97950537 | N33: 1000000000 | O33: 0.97950537

Sheet SawBones_TOF
C2: [Mpa] | G2: Valores de TOF
B3: PCF | C3: Mod E | D3: TOF | G3: PCF05 | H3: PCF08 | I3: PCF10 | J3: PCF12 | K3: PCF15 | L3: PCF20 | M3: PCF30
B4: 5 | C4: 16 | D4: =G21 -> 0.0019726948 | G4: 0.0019336315 | H4: 0.0017773785 | I4: 0.0017383152 | J4: 0.0015820621 | K4: 0.0014648724 | L4: 0.0013086193 | M4: 0.0011523663
B5: 8 | C5: 38 | D5: =H20 -> 0.0017578468 | G5: 0.0019726948 | H5: 0.0017578468 | I5: 0.0016601887 | J5: 0.0015429989 | K5: 0.0014453407 | L5: 0.0013086193 | M5: 0.0011523663
B6: 10 | C6: 58 | D6: =I21 -> 0.0016211254 | G6: 0.0019140999 | H6: 0.0016992519 | I6: 0.0016797203 | J6: 0.0015429989 | K6: 0.0014453407 | L6: 0.0012890877 | M6: 0.0011328346
B7: 12 | C7: 81 | D7: =J20 -> 0.0015820621 | G7: 0.0019336315 | H7: 0.0017187836 | I7: 0.0016797203 | J7: 0.0015234673 | K7: 0.0014453407 | L7: 0.0013086193 | M7: 0.0011718979
B8: 15 | C8: 123 | D8: =K20 -> 0.0014453407 | G8: 0.0019140999 | H8: 0.0017383152 | I8: 0.0016601887 | J8: 0.0015429989 | K8: 0.0014453407 | L8: 0.0012890877 | M8: 0.0011328346
B9: 20 | C9: 210 | D9: =L20 -> 0.0013086193 | G9: 0.0019140999 | H9: 0.0018164417 | I9: 0.0017773785 | J9: 0.0016015938 | K9: 0.0014648724 | L9: 0.0014062775 | M9: 0.0011328346
B10: 30 | C10: 415 | D10: =M20 -> 0.001113303 | G10: 0.001855505 | H10: 0.0017578468 | I10: 0.0017187836 | J10: 0.0015820621 | K10: 0.0014453407 | L10: 0.0013476826 | M10: 0.001113303
G11: 0.0018750366 | H11: 0.0017578468 | I11: 0.0016992519 | J11: 0.0015820621 | K11: 0.0014453407 | L11: 0.0013281509 | M11: 0.0011328346
G12: 0.0018945683 | H12: 0.0017187836 | I12: 0.0016992519 | J12: 0.0015820621 | K12: 0.0014648724 | L12: 0.0013476826 | M12: 0.0011328346
G13: 0.0019726948 | H13: 0.0017578468 | I13: 0.0016211254 | J13: 0.0015820621 | K13: 0.0014648724 | L13: 0.0014062775 | M13: 0.001113303
G14: 0.0019336315 | H14: 0.0018945683 | I14: 0.0017187836 | J14: 0.0015820621 | K14: 0.0014453407 | L14: 0.0013476826 | M14: 0.001113303
G15: 0.0019336315 | H15: 0.0017969101 | I15: 0.0016211254 | J15: 0.0015429989 | K15: 0.0014258091 | L15: 0.0013281509 | M15: 0.001113303
G16: 0.0019336315 | H16: 0.0017773785 | I16: 0.0016211254 | J16: 0.0015625305 | K16: 0.0014258091 | L16: 0.0013476826 | M16: 0.0010937714
H17: 0.0017578468 | I17: 0.001640657
H18: 0.0017383152 | I18: 0.0016211254
H19: 0.0017383152
F20: TOFs | G20: {=_xlfn.MODE.MULT(G4:G19)} -> 0.0019336315 | H20: {=_xlfn.MODE.MULT(H4:H19)} -> 0.0017578468 | I20: {=_xlfn.MODE.MULT(I4:I19)} -> 0.0017187836 | J20: {=_xlfn.MODE.MULT(J4:J19)} -> 0.0015820621 | K20: {=_xlfn.MODE.MULT(K4:K19)} -> 0.0014453407 | L20: {=_xlfn.MODE.MULT(L4:L19)} -> 0.0013086193 | M20: {=_xlfn.MODE.MULT(M4:M19)} -> 0.001113303
G21: =G5 -> 0.0019726948 | I21: 0.0016211254
I22: 0.0016211254

Sheet ConPlaca#1
P2: MAX | Q2: =MAX(P4:P385) -> 1.4926679 | T2: MAX | U2: =MAX(T4:T385) -> 1.4813529 | X2: MAX | Y2: =MAX(X4:X385) -> 1.6139001 | AC2: MAX | AD2: =MAX(AB4:AB385) -> 1.6142234
N3: TOF #1 | Q3: Normalized | R3: TOF #2 | U3: Normalized | V3: TOF #3 | Y3: Normalized | Z3: TOF #4 | AC3: Normalized
N4: 72.885304 | O4: =N4-$N$4 -> 0 | P4: 0.001996126 | Q4: =P4/$Q$2 -> 0.0013372874 | R4: 24.031463 | S4: =R4-$R$4 -> 0 | T4: 0.009431704 | U4: =T4/$U$2 -> 0.006366953 | V4: 51.981606 | W4: =V4-$V$4 -> 0 | X4: -0.003823022 | Y4: =X4/$Y$2 -> -0.0023688095 | Z4: 62.996889 | AA4: =Z4-$Z$4 -> 0 | AB4: 0.006198844 | AC4: =AB4/$AD$2 -> 0.0038401401
F5: M4_56_Mod_ConPlaca - PabloMajo2 | N5: 72.885314 | O5: =N5-$N$4 -> 1.00001e-05 | P5: -0.009965456 | Q5: =P5/$Q$2 -> -0.0066762715 | R5: 24.031473 | S5: =R5-$R$4 -> 1.00001e-05 | T5: -0.001236734 | U5: =T5/$U$2 -> -0.00083486793 | V5: 51.981616 | W5: =V5-$V$4 -> 1.00001e-05 | X5: -0.00156002 | Y5: =X5/$Y$2 -> -0.00096661496 | Z5: 62.996899 | AA5: =Z5-$Z$4 -> 1.00001e-05 | AB5: 0.002642698 | AC5: =AB5/$AD$2 -> 0.0016371327
N6: 72.885324 | O6: =N6-$N$4 -> 2.00002e-05 | P6: 0.00167284 | Q6: =P6/$Q$2 -> 0.0011207048 | R6: 24.031483 | S6: =R6-$R$4 -> 2.00002e-05 | T6: 0.002965984 | U6: =T6/$U$2 -> 0.002002213 | V6: 51.981626 | W6: =V6-$V$4 -> 2.00002e-05 | X6: -0.005439452 | Y6: =X6/$Y$2 -> -0.0033703771 | Z6: 62.996909 | AA6: =Z6-$Z$4 -> 2.00002e-05 | AB6: 0.002965984 | AC6: =AB6/$AD$2 -> 0.0018374061
N7: 72.885334 | O7: =N7-$N$4 -> 3.00003e-05 | P7: -0.002853164 | Q7: =P7/$Q$2 -> -0.0019114527 | R7: 24.031493 | S7: =R7-$R$4 -> 3.00003e-05 | T7: -0.003499736 | U7: =T7/$U$2 -> -0.0023625269 | V7: 51.981636 | W7: =V7-$V$4 -> 3.00003e-05 | X7: 0.001026268 | Y7: =X7/$Y$2 -> 0.00063589313 | Z7: 62.996919 | AA7: =Z7-$Z$4 -> 3.00003e-05 | AB7: 0.00652213 | AC7: =AB7/$AD$2 -> 0.0040404135
N8: 72.885344 | O8: =N8-$N$4 -> 4.00004e-05 | P8: -0.010935314 | Q8: =P8/$Q$2 -> -0.0073260195 | R8: 24.031503 | S8: =R8-$R$4 -> 4.00004e-05 | T8: 0.008461846 | U8: =T8/$U$2 -> 0.005712242 | V8: 51.981646 | W8: =V8-$V$4 -> 4.00004e-05 | X8: -0.002206592 | Y8: =X8/$Y$2 -> -0.001367242 | Z8: 62.996929 | AA8: =Z8-$Z$4 -> 4.00004e-05 | AB8: -0.004146308 | AC8: =AB8/$AD$2 -> -0.0025686085
N9: 72.885354 | O9: =N9-$N$4 -> 5.00005e-05 | P9: 0.000379696 | Q9: =P9/$Q$2 -> 0.00025437407 | R9: 24.031513 | S9: =R9-$R$4 -> 5.00005e-05 | T9: 0.01298785 | U9: =T9/$U$2 -> 0.0087675599 | V9: 51.981656 | W9: =V9-$V$4 -> 5.00005e-05 | X9: -0.002529878 | Y9: =X9/$Y$2 -> -0.0015675555 | Z9: 62.996939 | AA9: =Z9-$Z$4 -> 5.00005e-05 | AB9: 0.013957708 | AC9: =AB9/$AD$2 -> 0.0086467015
N10: 72.885364 | O10: =N10-$N$4 -> 6.00006e-05 | P10: -0.000266876 | Q10: =P10/$Q$2 -> -0.00017879128 | R10: 24.031523 | S10: =R10-$R$4 -> 6.00006e-05 | T10: 0.010724848 | U10: =T10/$U$2 -> 0.007239901 | V10: 51.981666 | W10: =V10-$V$4 -> 6.00006e-05 | X10: -0.005116166 | Y10: =X10/$Y$2 -> -0.0031700636 | Z10: 62.996949 | AA10: =Z10-$Z$4 -> 6.00006e-05 | AB10: 0.006845416 | AC10: =AB10/$AD$2 -> 0.0042406869
N11: 72.885374 | O11: =N11-$N$4 -> 7.00007e-05 | P11: -0.007379168 | Q11: =P11/$Q$2 -> -0.0049436101 | R11: 24.031533 | S11: =R11-$R$4 -> 7.00007e-05 | T11: -0.000266876 | U11: =T11/$U$2 -> -0.00018015694 | V11: 51.981676 | W11: =V11-$V$4 -> 7.00007e-05 | X11: -0.007379168 | Y11: =X11/$Y$2 -> -0.0045722582 | Z11: 62.996959 | AA11: =Z11-$Z$4 -> 7.00007e-05 | AB11: 5.641e-05 | AC11: =AB11/$AD$2 -> 3.4945597e-05
N12: 72.885384 | O12: =N12-$N$4 -> 8.00008e-05 | P12: 0.001026268 | Q12: =P12/$Q$2 -> 0.00068753942 | R12: 24.031543 | S12: =R12-$R$4 -> 8.00008e-05 | T12: -0.009318884 | U12: =T12/$U$2 -> -0.0062907929 | V12: 51.981686 | W12: =V12-$V$4 -> 8.00008e-05 | X12: -0.003499736 | Y12: =X12/$Y$2 -> -0.002168496 | Z12: 62.996969 | AA12: =Z12-$Z$4 -> 8.00008e-05 | AB12: -0.000913448 | AC12: =AB12/$AD$2 -> -0.00056587458
N13: 72.885394 | O13: =N13-$N$4 -> 9.00009e-05 | P13: 0.003935842 | Q13: =P13/$Q$2 -> 0.0026367835 | R13: 24.031553 | S13: =R13-$R$4 -> 9.00009e-05 | T13: 0.001349554 | U13: =T13/$U$2 -> 0.00091102804 | V13: 51.981696 | W13: =V13-$V$4 -> 9.00009e-05 | X13: -0.005439452 | Y13: =X13/$Y$2 -> -0.0033703771 | Z13: 62.996979 | AA13: =Z13-$Z$4 -> 9.00009e-05 | AB13: 0.001349554 | AC13: =AB13/$AD$2 -> 0.00083603917
N14: 72.885404 | O14: =N14-$N$4 -> 0.000100001 | P14: -0.004469594 | Q14: =P14/$Q$2 -> -0.0029943661 | R14: 24.031563 | S14: =R14-$R$4 -> 0.000100001 | T14: 0.004582414 | U14: =T14/$U$2 -> 0.003093398 | V14: 51.981706 | W14: =V14-$V$4 -> 0.000100001 | X14: 0.001349554 | Y14: =X14/$Y$2 -> 0.00083620664 | Z14: 62.996989 | AA14: =Z14-$Z$4 -> 0.000100001 | AB14: 0.002965984 | AC14: =AB14/$AD$2 -> 0.0018374061
N15: 72.885414 | O15: =N15-$N$4 -> 0.0001100011 | P15: -0.00640931 | Q15: =P15/$Q$2 -> -0.0042938621 | R15: 24.031573 | S15: =R15-$R$4 -> 0.0001100011 | T15: 0.003935842 | U15: =T15/$U$2 -> 0.002656924 | V15: 51.981716 | W15: =V15-$V$4 -> 0.0001100011 | X15: -0.011581886 | Y15: =X15/$Y$2 -> -0.0071763338 | Z15: 62.996999 | AA15: =Z15-$Z$4 -> 0.0001100011 | AB15: -0.003823022 | AC15: =AB15/$AD$2 -> -0.0023683351
N16: 72.885424 | O16: =N16-$N$4 -> 0.0001200012 | P16: -0.00156002 | Q16: =P16/$Q$2 -> -0.001045122 | R16: 24.031583 | S16: =R16-$R$4 -> 0.0001200012 | T16: -0.001883306 | U16: =T16/$U$2 -> -0.0012713419 | V16: 51.981726 | W16: =V16-$V$4 -> 0.0001200012 | X16: -0.007055882 | Y16: =X16/$Y$2 -> -0.0043719446 | Z16: 62.997009 | AA16: =Z16-$Z$4 -> 0.0001200012 | AB16: 0.001996126 | AC16: =AB16/$AD$2 -> 0.001236586
N17: 72.885434 | O17: =N17-$N$4 -> 0.0001300013 | P17: 0.001026268 | Q17: =P17/$Q$2 -> 0.00068753942 | R17: 24.031593 | S17: =R17-$R$4 -> 0.0001300013 | T17: 5.641e-05 | U17: =T17/$U$2 -> 3.8080056e-05 | V17: 51.981736 | W17: =V17-$V$4 -> 0.0001300013 | X17: -0.002529878 | Y17: =X17/$Y$2 -> -0.0015675555 | Z17: 62.997019 | AA17: =Z17-$Z$4 -> 0.0001300013 | AB17: 0.003612556 | AC17: =AB17/$AD$2 -> 0.0022379529
... N234: 72.887604 | O234: =N234-$N$4 -> 0.002300023 | P234: -0.018694178 | Q234: =P234/$Q$2 -> -0.012524004 | R234: 24.033763 | S234: =R234-$R$4 -> 0.002300023 | T234: -0.02095718 | U234: =T234/$U$2 -> -0.014147325 | V234: 51.983906 | W234: =V234-$V$4 -> 0.002300023 | X234: -0.020633894 | Y234: =X234/$Y$2 -> -0.012785112 | Z234: 62.999189 | AA234: =Z234-$Z$4 -> 0.002300023 | AB234: -0.014814746 | AC234: =AB234/$AD$2 -> -0.0091776305
N235: 72.887614 | P235: -0.02419004 | Q235: =P235/$Q$2 -> -0.016205909 | U235: =T235/$U$2 -> 0 | Y235: =X235/$Y$2 -> 0 | AC235: =AB235/$AD$2 -> 0
N236: 72.887624 | P236: -0.020633894 | Q236: =P236/$Q$2 -> -0.0138235 | U236: =T236/$U$2 -> 0 | Y236: =X236/$Y$2 -> 0 | AC236: =AB236/$AD$2 -> 0
N237: 72.887634 | P237: -0.03065576 | Q237: =P237/$Q$2 -> -0.020537563 | U237: =T237/$U$2 -> 0 | Y237: =X237/$Y$2 -> 0 | AC237: =AB237/$AD$2 -> 0
N238: 72.887644 | P238: -0.03227219 | Q238: =P238/$Q$2 -> -0.021620476 | U238: =T238/$U$2 -> 0 | Y238: =X238/$Y$2 -> 0 | AC238: =AB238/$AD$2 -> 0
N239: 72.887654 | P239: -0.028716044 | Q239: =P239/$Q$2 -> -0.019238067 | U239: =T239/$U$2 -> 0 | Y239: =X239/$Y$2 -> 0 | AC239: =AB239/$AD$2 -> 0
N240: 72.887664 | P240: -0.001883306 | Q240: =P240/$Q$2 -> -0.0012617047 | U240: =T240/$U$2 -> 0 | Y240: =X240/$Y$2 -> 0 | AC240: =AB240/$AD$2 -> 0
N241: 72.887674 | P241: 0.14973783 | Q241: =P241/$Q$2 -> 0.10031557 | U241: =T241/$U$2 -> 0 | Y241: =X241/$Y$2 -> 0 | AC241: =AB241/$AD$2 -> 0
N242: 72.887684 | P242: 0.1342201 | Q242: =P242/$Q$2 -> 0.089919601 | U242: =T242/$U$2 -> 0 | Y242: =X242/$Y$2 -> 0 | AC242: =AB242/$AD$2 -> 0
N243: 72.887694 | P243: 0.078614908 | Q243: =P243/$Q$2 -> 0.052667381 | U243: =T243/$U$2 -> 0 | Y243: =X243/$Y$2 -> 0 | AC243: =AB243/$AD$2 -> 0
N244: 72.887704 | P244: 0.005228986 | Q244: =P244/$Q$2 -> 0.0035031142 | U244: =T244/$U$2 -> 0 | Y244: =X244/$Y$2 -> 0 | AC244: =AB244/$AD$2 -> 0
N245: 72.887714 | P245: 0.13389681 | Q245: =P245/$Q$2 -> 0.089703019 | U245: =T245/$U$2 -> 0 | Y245: =X245/$Y$2 -> 0 | AC245: =AB245/$AD$2 -> 0
N246: 72.887724 | P246: 0.10609422 | Q246: =P246/$Q$2 -> 0.071076909 | U246: =T246/$U$2 -> 0 | Y246: =X246/$Y$2 -> 0 | AC246: =AB246/$AD$2 -> 0
... N384: 72.889104 | P384: -0.01287503 | Q384: =P384/$Q$2 -> -0.0086255156 | U384: =T384/$U$2 -> 0 | Y384: =X384/$Y$2 -> 0 | AC384: =AB384/$AD$2 -> 0

Sheet SinPlaca#1 
P3: MAX | Q3: =MAX(P5:P385) -> 1.3022524 | T3: MAX | U3: =MAX(T5:T385) -> 1.5799551 | X3: MAX | Y3: =MAX(X5:X385) -> 1.4787666 | AB3: MAX | AC3: =MAX(AB5:AB385) -> 1.4664817
N4: TOF #1 | Q4: Normalized | R4: TOF #2 | U4: Normalized | V4: TOF #3 | Y4: Normalized | Z4: TOF #4 | AC4: Normalized
N5: 7.3542044 | O5: =N5-$N$5 -> 0 | P5: -0.008349026 | Q5: =P5/$Q$3 -> -0.0064112194 | R5: 17.602806 | S5: =R5-$R$5 -> 0 | T5: 0.011048134 | U5: =T5/$U$3 -> 0.0069926886 | V5: 41.955256 | W5: =V5-$V$5 -> 0 | X5: 0.0049057 | Y5: =X5/$Y$3 -> 0.0033174269 | Z5: 51.133557 | AA5: =Z5-$Z$5 -> 0 | AB5: -0.002206592 | AC5: =AB5/$AC$3 -> -0.0015046843
F6: M4_56_Mod_SinPlaca - PabloMajo2 | N6: 7.3542144 | O6: =N6-$N$5 -> 1.00001e-05 | P6: -0.000266876 | Q6: =P6/$Q$3 -> -0.00020493416 | R6: 17.602816 | S6: =R6-$R$5 -> 1.00001e-05 | T6: 0.004582414 | U6: =T6/$U$3 -> 0.0029003445 | V6: 41.955266 | W6: =V6-$V$5 -> 1.00001e-05 | X6: -0.002853164 | Y6: =X6/$Y$3 -> -0.0019294215 | Z6: 51.133567 | AA6: =Z6-$Z$5 -> 1.00001e-05 | AB6: -0.002529878 | AC6: =AB6/$AC$3 -> -0.0017251344
N7: 7.3542244 | O7: =N7-$N$5 -> 2.00002e-05 | P7: -0.010612028 | Q7: =P7/$Q$3 -> -0.0081489793 | R7: 17.602826 | S7: =R7-$R$5 -> 2.00002e-05 | T7: 0.00328927 | U7: =T7/$U$3 -> 0.0020818756 | V7: 41.955276 | W7: =V7-$V$5 -> 2.00002e-05 | X7: -0.002853164 | Y7: =X7/$Y$3 -> -0.0019294215 | Z7: 51.133577 | AA7: =Z7-$Z$5 -> 2.00002e-05 | AB7: 0.00167284 | AC7: =AB7/$AC$3 -> 0.0011407166
N8: 7.3542344 | O8: =N8-$N$5 -> 3.00003e-05 | P8: -0.007379168 | Q8: =P8/$Q$3 -> -0.0056664652 | R8: 17.602836 | S8: =R8-$R$5 -> 3.00003e-05 | T8: 0.010078276 | U8: =T8/$U$3 -> 0.006378837 | V8: 41.955286 | W8: =V8-$V$5 -> 3.00003e-05 | X8: 0.00167284 | Y8: =X8/$Y$3 -> 0.0011312401 | Z8: 51.133587 | AA8: =Z8-$Z$5 -> 3.00003e-05 | AB8: 0.002642698 | AC8: =AB8/$AC$3 -> 0.0018020668
N9: 7.3542444 | O9: =N9-$N$5 -> 4.00004e-05 | P9: -0.007379168 | Q9: =P9/$Q$3 -> -0.0056664652 | R9: 17.602846 | S9: =R9-$R$5 -> 4.00004e-05 | T9: -0.00317645 | U9: =T9/$U$3 -> -0.0020104685 | V9: 41.955296 | W9: =V9-$V$5 -> 4.00004e-05 | X9: 0.00167284 | Y9: =X9/$Y$3 -> 0.0011312401 | Z9: 51.133597 | AA9: =Z9-$Z$5 -> 4.00004e-05 | AB9: 0.005875558 | AC9: =AB9/$AC$3 -> 0.0040065675
N10: 7.3542544 | O10: =N10-$N$5 -> 5.00005e-05 | P10: -0.007055882 | Q10: =P10/$Q$3 -> -0.0054182138 | R10: 17.602856 | S10: =R10-$R$5 -> 5.00005e-05 | T10: 0.007491988 | U10: =T10/$U$3 -> 0.0047418993 | V10: 41.955306 | W10: =V10-$V$5 -> 5.00005e-05 | X10: -0.00156002 | Y10: =X10/$Y$3 -> -0.0010549468 | Z10: 51.133607 | AA10: =Z10-$Z$5 -> 5.00005e-05 | AB10: 0.002642698 | AC10: =AB10/$AC$3 -> 0.0018020668
N11: 7.3542644 | O11: =N11-$N$5 -> 6.00006e-05 | P11: 0.000379696 | Q11: =P11/$Q$3 -> 0.00029156867 | R11: 17.602866 | S11: =R11-$R$5 -> 6.00006e-05 | T11: 0.003612556 | U11: =T11/$U$3 -> 0.0022864928 | V11: 41.955316 | W11: =V11-$V$5 -> 6.00006e-05 | X11: -0.002853164 | Y11: =X11/$Y$3 -> -0.0019294215 | Z11: 51.133617 | AA11: =Z11-$Z$5 -> 6.00006e-05 | AB11: 0.001026268 | AC11: =AB11/$AC$3 -> 0.00069981644
N12: 7.3542744 | O12: =N12-$N$5 -> 7.00007e-05 | P12: -0.005439452 | Q12: =P12/$Q$3 -> -0.0041769567 | R12: 17.602876 | S12: =R12-$R$5 -> 7.00007e-05 | T12: 0.002319412 | U12: =T12/$U$3 -> 0.001468024 | V12: 41.955326 | W12: =V12-$V$5 -> 7.00007e-05 | X12: -0.000266876 | Y12: =X12/$Y$3 -> -0.00018047203 | Z12: 51.133627 | AA12: =Z12-$Z$5 -> 7.00007e-05 | AB12: 0.001349554 | AC12: =AB12/$AC$3 -> 0.00092026651
N13: 7.3542844 | O13: =N13-$N$5 -> 8.00008e-05 | P13: -0.005439452 | Q13: =P13/$Q$3 -> -0.0041769567 | R13: 17.602886 | S13: =R13-$R$5 -> 8.00008e-05 | T13: -0.001883306 | U13: =T13/$U$3 -> -0.0011919997 | V13: 41.955336 | W13: =V13-$V$5 -> 8.00008e-05 | X13: 0.001996126 | Y13: =X13/$Y$3 -> 0.0013498588 | Z13: 51.133637 | AA13: =Z13-$Z$5 -> 8.00008e-05 | AB13: 0.000379696 | AC13: =AB13/$AC$3 -> 0.00025891629
N14: 7.3542944 | O14: =N14-$N$5 -> 9.00009e-05 | P14: -0.008995598 | Q14: =P14/$Q$3 -> -0.0069077222 | R14: 17.602896 | S14: =R14-$R$5 -> 9.00009e-05 | T14: -0.000266876 | U14: =T14/$U$3 -> -0.00016891366 | V14: 41.955346 | W14: =V14-$V$5 -> 9.00009e-05 | X14: -0.002206592 | Y14: =X14/$Y$3 -> -0.0014921841 | Z14: 51.133647 | AA14: =Z14-$Z$5 -> 9.00009e-05 | AB14: 0.001349554 | AC14: =AB14/$AC$3 -> 0.00092026651
N15: 7.3543044 | O15: =N15-$N$5 -> 0.000100001 | P15: -0.00802574 | Q15: =P15/$Q$3 -> -0.006162968 | R15: 17.602906 | S15: =R15-$R$5 -> 0.000100001 | T15: 0.010401562 | U15: =T15/$U$3 -> 0.0065834542 | V15: 41.955356 | W15: =V15-$V$5 -> 0.000100001 | X15: -0.004146308 | Y15: =X15/$Y$3 -> -0.0028038962 | Z15: 51.133657 | AA15: =Z15-$Z$5 -> 0.000100001 | AB15: 0.001026268 | AC15: =AB15/$AC$3 -> 0.00069981644
N16: 7.3543144 | O16: =N16-$N$5 -> 0.0001100011 | P16: -0.00964217 | Q16: =P16/$Q$3 -> -0.0074042251 | R16: 17.602916 | S16: =R16-$R$5 -> 0.0001100011 | T16: 0.008461846 | U16: =T16/$U$3 -> 0.005355751 | V16: 41.955366 | W16: =V16-$V$5 -> 0.0001100011 | X16: -0.00156002 | Y16: =X16/$Y$3 -> -0.0010549468 | Z16: 51.133667 | AA16: =Z16-$Z$5 -> 0.0001100011 | AB16: 0.00167284 | AC16: =AB16/$AC$3 -> 0.0011407166
N17: 7.3543244 | O17: =N17-$N$5 -> 0.0001200012 | P17: -0.00640931 | Q17: =P17/$Q$3 -> -0.004921711 | R17: 17.602926 | S17: =R17-$R$5 -> 0.0001200012 | T17: 0.001996126 | U17: =T17/$U$3 -> 0.0012634068 | V17: 41.955376 | W17: =V17-$V$5 -> 0.0001200012 | X17: -0.00156002 | Y17: =X17/$Y$3 -> -0.0010549468 | Z17: 51.133677 | AA17: =Z17-$Z$5 -> 0.0001200012 | AB17: 0.001026268 | AC17: =AB17/$AC$3 -> 0.00069981644
N18: 7.3543344 | O18: =N18-$N$5 -> 0.0001300013 | P18: -0.004146308 | Q18: =P18/$Q$3 -> -0.0031839511 | R18: 17.602936 | S18: =R18-$R$5 -> 0.0001300013 | T18: 0.002965984 | U18: =T18/$U$3 -> 0.0018772584 | V18: 41.955386 | W18: =V18-$V$5 -> 0.0001300013 | X18: -0.00479288 | Y18: =X18/$Y$3 -> -0.0032411336 | Z18: 51.133687 | AA18: =Z18-$Z$5 -> 0.0001300013 | AB18: 0.001349554 | AC18: =AB18/$AC$3 -> 0.00092026651
... N235: 7.3565044 | O235: =N235-$N$5 -> 0.002300023 | P235: 0.043053448 | Q235: =P235/$Q$3 -> 0.033060755 | R235: 17.605106 | S235: =R235-$R$5 -> 0.002300023 | T235: 0.065360182 | U235: =T235/$U$3 -> 0.04136838 | V235: 41.957556 | W235: =V235-$V$5 -> 0.002300023 | X235: -0.055872068 | Y235: =X235/$Y$3 -> -0.037782885 | Z235: 51.135857 | AA235: =Z235-$Z$5 -> 0.002300023 | AB235: 0.060834178 | AC235: =AB235/$AC$3 -> 0.04148308
M236: Hasta Aqui | N236: 7.3565144 | P236: 0.046286308 | Q236: =P236/$Q$3 -> 0.035543269 | R236: 17.605116 | T236: 0.052428742 | U236: =T236/$U$3 -> 0.033183691 | V236: 41.957566 | X236: -0.03227219 | Y236: =X236/$Y$3 -> -0.021823722 | Z236: 51.135867 | AB236: 0.099305212 | AC236: =AB236/$AC$3 -> 0.067716639
N237: 7.3565244 | P237: 0.073119046 | Q237: =P237/$Q$3 -> 0.056148136 | R237: 17.605126 | T237: 0.047256166 | U237: =T237/$U$3 -> 0.029909816 | V237: 41.957576 | X237: -0.011905172 | Y237: =X237/$Y$3 -> -0.0080507446 | Z237: 51.135877 | AB237: 0.14230225 | AC237: =AB237/$AC$3 -> 0.097036499
N238: 7.3565344 | P238: 0.13098724 | Q238: =P238/$Q$3 -> 0.10058514 | R238: 17.605136 | T238: 0.0372343 | U238: =T238/$U$3 -> 0.023566682 | V238: 41.957586 | X238: 0.10480107 | Y238: =X238/$Y$3 -> 0.0708706 | Z238: 51.135887 | AB238: 0.19047186 | AC238: =AB238/$AC$3 -> 0.12988356
N239: 7.3565444 | P239: 0.1481214 | Q239: =P239/$Q$3 -> 0.11374246 | R239: 17.605146 | T239: 0.01622071 | U239: =T239/$U$3 -> 0.010266564 | V239: 41.957596 | X239: -0.003499736 | Y239: =X239/$Y$3 -> -0.0023666589 | Z239: 51.135897 | AB239: 0.21859775 | AC239: =AB239/$AC$3 -> 0.14906272
N240: 7.3565544 | P240: 0.10577093 | Q240: =P240/$Q$3 -> 0.081221529 | R240: 17.605156 | T240: 0.015897424 | U240: =T240/$U$3 -> 0.010061947 | V240: 41.957606 | X240: 0.008461846 | Y240: =X240/$Y$3 -> 0.0057222324 | Z240: 51.135907 | AB240: 0.24187434 | AC240: =AB240/$AC$3 -> 0.16493512
N241: 7.3565644 | P241: 0.058894462 | Q241: =P241/$Q$3 -> 0.045225074 | R241: 17.605166 | T241: 0.017190568 | U241: =T241/$U$3 -> 0.010880416 | V241: 41.957616 | X241: 0.078938194 | Y241: =X241/$Y$3 -> 0.053381105 | Z241: 51.135917 | AB241: 0.24187434 | AC241: =AB241/$AC$3 -> 0.16493512
N242: 7.3565744 | P242: 0.036911014 | Q242: =P242/$Q$3 -> 0.028343978 | R242: 17.605176 | T242: 5.641e-05 | U242: =T242/$U$3 -> 3.5703546e-05 | V242: 41.957626 | X242: 0.075382048 | Y242: =X242/$Y$3 -> 0.0509763 | Z242: 51.135927 | AB242: 0.22474018 | AC242: =AB242/$AC$3 -> 0.15325127
N243: 7.3565844 | P243: 0.036587728 | Q243: =P243/$Q$3 -> 0.028095727 | R243: 17.605186 | T243: -0.029362616 | U243: =T243/$U$3 -> -0.018584462 | V243: 41.957636 | X243: 0.021393286 | Y243: =X243/$Y$3 -> 0.01446698 | Z243: 51.135937 | AB243: 0.18756229 | AC243: =AB243/$AC$3 -> 0.12789951
N244: 7.3565944 | P244: 0.060834178 | Q244: =P244/$Q$3 -> 0.046714582 | R244: 17.605196 | T244: -0.049406348 | U244: =T244/$U$3 -> -0.031270729 | V244: 41.957646 | X244: 0.070532758 | Y244: =X244/$Y$3 -> 0.047697019 | Z244: 51.135947 | AB244: 0.15943641 | AC244: =AB244/$AC$3 -> 0.10872035
N245: 7.3566044 | P245: -0.017401034 | Q245: =P245/$Q$3 -> -0.013362259 | R245: 17.605206 | T245: -0.021927038 | U245: =T245/$U$3 -> -0.013878267 | V245: 41.957656 | X245: 0.095749066 | Y245: =X245/$Y$3 -> 0.064749277 | Z245: 51.135957 | AB245: 0.12419823 | AC245: =AB245/$AC$3 -> 0.084691294
N246: 7.3566144 | P246: 0.000702982 | Q246: =P246/$Q$3 -> 0.00053982008 | R246: 17.605216 | T246: 0.010724848 | U246: =T246/$U$3 -> 0.0067880714 | V246: 41.957666 | X246: 0.13518996 | Y246: =X246/$Y$3 -> 0.091420756 | Z246: 51.135967 | AB246: 0.10480107 | AC246: =AB246/$AC$3 -> 0.07146429
N247: 7.3566244 | P247: 0.026565862 | Q247: =P247/$Q$3 -> 0.020399933 | R247: 17.605226 | T247: 0.01945357 | U247: =T247/$U$3 -> 0.012312736 | V247: 41.957676 | X247: 0.15006111 | Y247: =X247/$Y$3 -> 0.10147722 | Z247: 51.135977 | AB247: 0.075705334 | AC247: =AB247/$AC$3 -> 0.051623783
N248: 7.3566344 | P248: 0.006845416 | Q248: =P248/$Q$3 -> 0.0052565969 | R248: 17.605236 | T248: -0.010935314 | U248: =T248/$U$3 -> -0.0069212815 | V248: 41.957686 | X248: 0.24122777 | Y248: =X248/$Y$3 -> 0.16312768 | Z248: 51.135987 | AB248: 0.062450608 | AC248: =AB248/$AC$3 -> 0.04258533
... N385: 7.3580045 | P385: -0.026129756 | Q385: =P385/$Q$3 -> -0.020065047 | R385: 17.606606 | T385: -0.02903933 | U385: =T385/$U$3 -> -0.018379845 | V385: 41.959056 | X385: -0.031948904 | Y385: =X385/$Y$3 -> -0.021605103 | Z385: 51.137357 | AB385: -0.019987322 | AC385: =AB385/$AC$3 -> -0.013629438

Sheet CurvasCompactación
B4: 56 Golpes Mod
B5: Humedad | C5: Den. Seca
B6: =[1]Mediciones!I36 -> 0.11805226 | C6: =[1]Mediciones!J36 -> 1.7637281
B7: =[1]Mediciones!I37 -> 0.096678108 | C7: =[1]Mediciones!J37 -> 1.6822689
B8: =[1]Mediciones!I38 -> 0.080713111 | C8: =[1]Mediciones!J38 -> 1.6483734 | L8: x2 | M8: x | N8: c
B9: =[1]Mediciones!I49 -> 0.14308617 | C9: =[1]Mediciones!J49 -> 1.7772422 | L9: -101.47 | M9: 28.233 | N9: -0.2656
B10: =[1]Mediciones!I50 -> 0.17279256 | C10: =[1]Mediciones!J50 -> 1.6951263 | K10: MAX | L10: =-M9/(L9*2) -> 0.13911994
B11: =[1]Mediciones!I51 -> 0.18634375 | C11: =[1]Mediciones!J51 -> 1.6321785 | K11: DENSIDAD | L11: =L10^2*L9+L10*M9+N9 -> 1.6982866
K12: 95% Opt. | L12: =L11*0.95 -> 1.6133723
B13: 25 Golpes Mod
B14: Humedad | C14: Den. Seca
B15: =[1]Mediciones!I35 -> 0.11843409 | C15: =[1]Mediciones!J35 -> 1.6584292
B16: =[1]Mediciones!I54 -> 0.13297333 | C16: =[1]Mediciones!J54 -> 1.686719 | L16: 1.5284579
B17: =[1]Mediciones!I55 -> 0.15578764 | C17: =[1]Mediciones!J55 -> 1.6784849
B18: =[1]Mediciones!I56 -> 0.16935065 | C18: =[1]Mediciones!J56 -> 1.6019546
B20: 25 Golpes EST
B21: Humedad | C21: Den. Seca
B22: 0.11589041 | C22: 1.4806779 | K22: 0.05
B23: 0.13460443 | C23: 1.490469 | K23: 0.21
B24: 0.1402803 | C24: 1.5294345
B25: 0.15156951 | C25: 1.5475075 | K25: 1.58
B26: 0.16556029 | C26: 1.6090049 | K26: 1.8
B27: 0.19470447 | C27: 1.6060303

Sheet Ceramica_TOFvsOndaP
B2: MEDICIÓN #1
B4: Datos Probetas | O4: Análisis Velocidad Onda P | AH4: Mod. E Pelotazo
B5: Probeta | C5: Energía | D5: Altura | E5: Diámetro | F5: Volumen | G5: Masa | H5: Densidad | I5: Humedad | J5: Den. Seca | K5: GS | L5: e | M5: Saturación | O5: Poisson | P5: TV1 | Q5: TV2 | R5: TV3 | S5: TV4 | T5: TV5 | AB5: TV prom | AD5: Mod E | AH5: TOF1 | AI5: TOF2 | AJ5: TOF3 | AK5: TOF4 | AL5: TOF5 | AM5: TOF Prom | AN5: E1 | AO5: E2 | AP5: E3 | AQ5: E4 | AR5: E5 | AT5: Mod E
B6: - | C6: Golpes | D6: mm | E6: mm | F6: cm3 | G6: g | H6: g/cm3 | I6: % | J6: g/cm3 | K6: - | L6: - | M6: % | O6: - | P6: us | Q6: us | R6: us | S6: us | T6: us | AB6: us | AD6: Mpa | AH6: s | AI6: s | AJ6: s | AK6: s | AL6: s | AM6: s | AN6: Mpa | AO6: Mpa | AP6: Mpa | AQ6: Mpa | AR6: Mpa | AT6: Mpa
B7: Masa 1 | C7: 25 | D7: 116.5 | E7: 102 | F7: =(D7/10)*(PI()/4)*((E7/10)^2) -> 951.95441 | G7: 1931.2 | H7: =G7/F7 -> 2.0286686 | I7: 0.13873393 | J7: =H7/(1+I7) -> 1.7815124 | K7: 2.5 | L7: =K7/J7-1 -> 0.40330208 | M7: =I7*(K7/L7) -> 0.85998771
B8: Masa 2 | C8: 25 | D8: 117.7 | E8: 101.8 | F8: =(D8/10)*(PI()/4)*((E8/10)^2) -> 957.99204 | G8: 1925 | H8: =G8/F8 -> 2.0094113 | I8: 0.1654157 | J8: =H8/(1+I8) -> 1.7242013 | K8: 2.5 | L8: =K8/J8-1 -> 0.44994671 | M8: =I8*(K8/L8) -> 0.91908497
B9: Masa 3 | C9: 25 | D9: 116.9 | E9: 101.1 | F9: =(D9/10)*(PI()/4)*((E9/10)^2) -> 938.44042 | G9: 1837 | H9: =G9/F9 -> 1.9575031 | I9: 0.1839677 | J9: =H9/(1+I9) -> 1.6533416 | K9: 2.5 | L9: =K9/J9-1 -> 0.5120892 | M9: =I9*(K9/L9) -> 0.89812333
B10: Masa 4 | C10: 25 | D10: =AVERAGE(D9,D12) -> 116.69 | E10: 102.2 | F10: =(D10/10)*(PI()/4)*((E10/10)^2) -> 957.24986 | G10: 1795.5 | H10: =G10/F10 -> 1.8756858 | I10: 0.10371452 | J10: =H10/(1+I10) -> 1.6994302 | K10: 2.5 | L10: =K10/J10-1 -> 0.47108128 | M10: =I10*(K10/L10) -> 0.55040674
B11: Masa 5 | C11: 25 | D11: 118.3 | E11: 101.5 | F11: =(D11/10)*(PI()/4)*((E11/10)^2) -> 957.20886 | G11: 1943.5 | H11: =G11/F11 -> 2.0303824 | I11: 0.15280665 | J11: =H11/(1+I11) -> 1.7612514 | K11: 2.5 | L11: =K11/J11-1 -> 0.41944526 | M11: =I11*(K11/L11) -> 0.91076636
B12: Masa 6 | C12: 25 | D12: 116.48 | E12: 101.8 | F12: =(D12/10)*(PI()/4)*((E12/10)^2) -> 948.06213 | G12: 1888.5 | H12: =G12/F12 -> 1.9919581 | I12: 0.17336269 | J12: =H12/(1+I12) -> 1.6976491 | K12: 2.5 | L12: =K12/J12-1 -> 0.47262474 | M12: =I12*(K12/L12) -> 0.9170208
B13: Masa 7 | C13: 25 | D13: 115.88 | E13: 101.5 | F13: =(D13/10)*(PI()/4)*((E13/10)^2) -> 937.62775 | G13: 1918.5 | H13: =G13/F13 -> 2.0461212 | I13: 0.19547775 | J13: =H13/(1+I13) -> 1.711551 | K13: 2.5 | L13: =K13/J13-1 -> 0.46066343 | M13: =I13*(K13/L13) -> 1.0608491
B15: MEDICIÓN #2
B17: Datos Probetas | O17: Análisis Velocidad Onda P | AH17: Mod. E Pelotazo
B18: Probeta | C18: Energía | D18: Altura | E18: Diámetro | F18: Volumen | G18: Masa | H18: Densidad | I18: Humedad | J18: Den. Seca | K18: GS | L18: e | M18: Saturación | O18: Poisson | P18: TV1 | Q18: TV2 | R18: TV3 | S18: TV4 | T18: TV5 | AB18: TV prom | AD18: Mod E | AH18: TOF1 | AI18: TOF2 | AJ18: TOF3 | AK18: TOF4 | AL18: TOF5 | AM18: TOF Prom | AN18: E1 | AO18: E2 | AP18: E3 | AQ18: E4 | AR18: E5 | AT18: Mod E
B19: - | C19: Golpes | D19: mm | E19: mm | F19: cm3 | G19: g | H19: g/cm3 | I19: % | J19: g/cm3 | K19: - | L19: - | M19: % | O19: - | P19: us | Q19: us | R19: us | S19: us | T19: us | AB19: us | AD19: Mpa | AH19: s | AI19: s | AJ19: s | AK19: s | AL19: s | AM19: s | AN19: Mpa | AO19: Mpa | AP19: Mpa | AQ19: Mpa | AR19: Mpa | AT19: Mpa
B20: Masa 1 | C20: 25 | D20: 116.6 | E20: 102.7 | F20: =(D20/10)*(PI()/4)*((E20/10)^2) -> 965.89367 | G20: 1886.25 | H20: =G20/F20 -> 1.9528547 | I20: 0.20908379 | J20: =H20/(1+I20) -> 1.6151525 | K20: 2.5 | L20: =K20/J20-1 -> 0.54784145 | M20: =I20*(K20/L20) -> 0.95412545
B21: Masa 2 | C21: 25 | D21: 117.7 | E21: 101.9 | F21: =(D21/10)*(PI()/4)*((E21/10)^2) -> 959.87507 | G21: 1876.16 | H21: =G21/F21 -> 1.9545877 | I21: 0.17261905 | J21: =H21/(1+I21) -> 1.6668565 | K21: 2.5 | L21: =K21/J21-1 -> 0.49982916 | M21: =I21*(K21/L21) -> 0.86339024
B22: Masa 3 | C22: 25 | D22: 116.3 | E22: 101.2 | F22: =(D22/10)*(PI()/4)*((E22/10)^2) -> 935.47163 | G22: 1771.46 | H22: =G22/F22 -> 1.8936544 | I22: 0.15281757 | J22: =H22/(1+I22) -> 1.6426315 | K22: 2.5 | L22: =K22/J22-1 -> 0.52194819 | M22: =I22*(K22/L22) -> 0.73195758
B23: Masa 4 | C23: 25 | D23: 119 | E23: 102 | F23: =(D23/10)*(PI()/4)*((E23/10)^2) -> 972.38262 | G23: 1591.26 | H23: =G23/F23 -> 1.6364546 | I23: 0.098525989 | J23: =H23/(1+I23) -> 1.4896822 | K23: 2.5 | L23: =K23/J23-1 -> 0.67821031 | M23: =I23*(K23/L23) -> 0.36318376
B24: Masa 1 | C24: 56 | D24: 119.6 | E24: 101.8 | F24: =(D24/10)*(PI()/4)*((E24/10)^2) -> 973.45665 | G24: 1936.8 | H24: =G24/F24 -> 1.9896109 | I24: 0.17013766 | J24: =H24/(1+I24) -> 1.7003221 | K24: 2.5 | L24: =K24/J24-1 -> 0.47030965 | M24: =I24*(K24/L24) -> 0.90439173
B25: Masa 2 | C25: 56 | D25: 118 | E25: 102.3 | F25: =(D25/10)*(PI()/4)*((E25/10)^2) -> 969.89151 | G25: 1740.16 | H25: =G25/F25 -> 1.7941801 | I25: 0.11027138 | J25: =H25/(1+I25) -> 1.6159833 | K25: 2.5 | L25: =K25/J25-1 -> 0.54704565 | M25: =I25*(K25/L25) -> 0.5039405
B26: Masa 3 | C26: 56 | D26: 116.8 | E26: 101.9 | F26: =(D26/10)*(PI()/4)*((E26/10)^2) -> 952.53533 | G26: 1903.78 | H26: =G26/F26 -> 1.998645 | I26: 0.18211382 | J26: =H26/(1+I26) -> 1.6907382 | K26: 2.5 | L26: =K26/J26-1 -> 0.47864404 | M26: =I26*(K26/L26) -> 0.95119654
B27: Masa 4 | C27: 56 | D27: 118 | E27: 101.7 | F27: =(D27/10)*(PI()/4)*((E27/10)^2) -> 958.54784 | G27: 1839.59 | H27: =G27/F27 -> 1.9191426 | I27: 0.14310051 | J27: =H27/(1+I27) -> 1.6788923 | K27: 2.5 | L27: =K27/J27-1 -> 0.48907709 | M27: =I27*(K27/L27) -> 0.73148239
B28: Masa 5 | C28: 56 | D28: 117.8 | E28: 102 | F28: =(D28/10)*(PI()/4)*((E28/10)^2) -> 962.57708 | G28: 1878.62 | H28: =G28/F28 -> 1.9516567 | I28: 0.21071013 | J28: =H28/(1+I28) -> 1.6119934 | K28: 2.5 | L28: =K28/J28-1 -> 0.55087487 | M28: =I28*(K28/L28) -> 0.95625223
B30: MEDICIÓN #3
B32: Datos Probetas | O32: Análisis Velocidad Onda P | AH32: Mod. E Pelotazo | AW32: Analisis Errores
B33: Probeta | C33: Energía | D33: Altura | E33: Diámetro | F33: Volumen | G33: Masa | H33: Densidad | I33: Humedad | J33: Den. Seca | K33: GS | L33: e | M33: Saturación | O33: Poisson | P33: TV1 | Q33: TV2 | R33: TV3 | S33: TV4 | T33: TV5 | V33: E1 | W33: E2 | X33: E3 | Y33: E4 | Z33: E5 | AA33: Ajuste | AB33: TV prom | AC33: desvest TV | AD33: Mod E | AE33: E prom | AF33: desvest E | AH33: TOF1 | AI33: TOF2 | AJ33: TOF3 | AK33: TOF4 | AL33: TOF5 | AM33: TOF Prom | AN33: E1 | AO33: E2 | AP33: E3 | AQ33: E4 | AR33: E5 | AS33: Mod E | AT33: Mod E | AU33: desvest E | AW33: Diferencia | AX33: % Error
B34: - | C34: Golpes | D34: mm | E34: mm | F34: cm3 | G34: g | H34: g/cm3 | I34: % | J34: g/cm3 | K34: - | L34: - | M34: % | O34: - | P34: us | Q34: us | R34: us | S34: us | T34: us | AB34: us | AD34: Mpa | AH34: s | AI34: s | AJ34: s | AK34: s | AL34: s | AM34: s | AN34: Mpa | AO34: Mpa | AP34: Mpa | AQ34: Mpa | AR34: Mpa | AS34: Average | AT34: Mpa | AW34: Mpa | AX34: %
B35: M1 - Mod | C35: 25 | D35: =AVERAGE(116.3,117.4,117.4) -> 117.03333 | E35: 101 | F35: =(D35/10)*(PI()/4)*((E35/10)^2) -> 937.65312 | G35: 1739.2 | H35: =G35/F35 -> 1.8548437 | I35: 0.11843409 | J35: =H35/(1+I35) -> 1.6584292 | K35: 2.5 | L35: =K35/J35-1 -> 0.50745058 | M35: =I35*(K35/L35) -> 0.583476 | O35: 0.2 | P35: 246.34 | Q35: 244.08 | R35: 254.25 | S35: 223.74 | T35: 256.51 | V35: =(((($D35/10)/P35)*10000)^2)*(($H35*1000*(1+$O35)*(1-2*($O35)))/(1-$O35))/1000000 -> 376.78977 | W35: =(((($D35/10)/Q35)*10000)^2)*(($H35*1000*(1+$O35)*(1-2*($O35)))/(1-$O35))/1000000 -> 383.79967 | X35: =(((($D35/10)/R35)*10000)^2)*(($H35*1000*(1+$O35)*(1-2*($O35)))/(1-$O35))/1000000 -> 353.70977 | Z35: =(((($D35/10)/T35)*10000)^2)*(($H35*1000*(1+$O35)*(1-2*($O35)))/(1-$O35))/1000000 -> 347.50446 | AA35: 100 | AB35: =AVERAGE(T35)+AA35 -> 356.51 | AC35: =_xlfn.STDEV.S(P35:T35) -> 12.96795 | AD35: =((((D35/10)/AB35)*10000)^2)*((H35*1000*(1+O35)*(1-2*(O35)))/(1-O35))/1000000 -> 179.89767 | AE35: =AD35 -> 179.89767 | AF35: =_xlfn.STDEV.S(V35:Z35) -> 17.561095 | AH35: 0.0013500135 | AI35: 0.0013200132 | AJ35: 0.0013700137 | AK35: 0.0013500135 | AL35: 0.0013700137 | AM35: =AVERAGE(AH35:AL35) -> 0.0013520135 | AN35: 224.27854 | AO35: 245.02019 | AP35: 210.45078 | AQ35: 224.27854 | AR35: 210.45078 | AS35: =AVERAGE(AN35:AR35) -> 222.89577 | AT35: 222.89555 | AU35: =_xlfn.STDEV.S(AN35:AR35) -> 14.169241 | AW35: =AD35-AT35 -> -42.997877 | AX35: =ABS(AW35)/AD35 -> 0.23901297
B36: M1 - Mod | C36: 56 | D36: =AVERAGE(116.5,116.2,116.4,116.3) -> 116.35 | E36: 101 | F36: =(D36/10)*(PI()/4)*((E36/10)^2) -> 932.17836 | G36: 1838.2 | H36: =G36/F36 -> 1.9719402 | I36: 0.11805226 | J36: =H36/(1+I36) -> 1.7637281 | K36: 2.5 | L36: =K36/J36-1 -> 0.41745202 | M36: =I36*(K36/L36) -> 0.70698099 | O36: 0.34 | P36: 308.49 | Q36: 341.26 | R36: 341.26 | S36: 359.34 | T36: 368.38 | V36: =(((($D36/10)/P36)*10000)^2)*(($H36*1000*(1+$O36)*(1-2*($O36)))/(1-$O36))/1000000 -> 182.24481 | W36: =(((($D36/10)/Q36)*10000)^2)*(($H36*1000*(1+$O36)*(1-2*($O36)))/(1-$O36))/1000000 -> 148.92465 | X36: =(((($D36/10)/R36)*10000)^2)*(($H36*1000*(1+$O36)*(1-2*($O36)))/(1-$O36))/1000000 -> 148.92465 | Y36: =(((($D36/10)/S36)*10000)^2)*(($H36*1000*(1+$O36)*(1-2*($O36)))/(1-$O36))/1000000 -> 134.31553 | Z36: =(((($D36/10)/T36)*10000)^2)*(($H36*1000*(1+$O36)*(1-2*($O36)))/(1-$O36))/1000000 -> 127.80424 | AA36: 0 | AB36: =P36 -> 308.49 | AC36: =_xlfn.STDEV.S(P36:T36) -> 22.942061 | AD36: =((((D36/10)/AB36)*10000)^2)*((H36*1000*(1+O36)*(1-2*(O36)))/(1-O36))/1000000 -> 182.24481 | AE36: =AD36 -> 182.24481 | AF36: =_xlfn.STDEV.S(V36:Z36) -> 21.027186 | AH36: 0.0013900139 | AI36: 0.0012600126 | AJ36: 0.0013400134 | AK36: 0.0013100131 | AL36: 0.0012900129 | AM36: =AVERAGE(AH36:AL36) -> 0.0013180132 | AN36: 180.60107 | AO36: 222.13458 | AP36: 242.90134 | AQ36: 256.74584 | AR36: 187.52332 | AS36: =AVERAGE(AN36:AR36) -> 217.98123 | AT36: 221.83875 | AU36: =_xlfn.STDEV.S(AN36:AP36) -> 31.721744 | AW36: =AD36-AT36 -> -39.593931 | AX36: =ABS(AW36)/AD36 -> 0.21725683
B37: M2 - Mod | C37: 56 | D37: =AVERAGE(116.3,116.7,116.5) -> 116.5 | E37: 101 | F37: =(D37/10)*(PI()/4)*((E37/10)^2) -> 933.38014 | G37: 1722 | H37: =G37/F37 -> 1.8449075 | I37: 0.096678108 | J37: =H37/(1+I37) -> 1.6822689 | K37: 2.5 | L37: =K37/J37-1 -> 0.48608821 | M37: =I37*(K37/L37) -> 0.49722512 | O37: 0.12 | P37: 243.97907 | Q37: 227.13 | R37: 195.49 | S37: 202.27 | T37: 235.04 | V37: =(((($D37/10)/P37)*10000)^2)*(($H37*1000*(1+$O37)*(1-2*($O37)))/(1-$O37))/1000000 -> 406.88367 | W37: =(((($D37/10)/Q37)*10000)^2)*(($H37*1000*(1+$O37)*(1-2*($O37)))/(1-$O37))/1000000 -> 469.49004 | Y37: =(((($D37/10)/S37)*10000)^2)*(($H37*1000*(1+$O37)*(1-2*($O37)))/(1-$O37))/1000000 -> 591.98736 | Z37: =(((($D37/10)/T37)*10000)^2)*(($H37*1000*(1+$O37)*(1-2*($O37)))/(1-$O37))/1000000 -> 438.42149 | AA37: 80 | AB37: =P37+AA37 -> 323.97907 | AC37: =_xlfn.STDEV.S(P37:T37) -> 21.000422 | AD37: =((((D37/10)/AB37)*10000)^2)*((H37*1000*(1+O37)*(1-2*(O37)))/(1-O37))/1000000 -> 230.74988 | AE37: =AD37 -> 230.74988 | AF37: =_xlfn.STDEV.S(V37:W37,Z37) -> 31.30348 | AH37: 0.0013300133 | AI37: 0.0012800128 | AJ37: 0.0012700127 | AK37: 0.0012500125 | AL37: 0.0012600126 | AM37: =AVERAGE(AH37:AL37) -> 0.0012780128 | AN37: 241.09728 | AO37: 275.69655 | AP37: 282.6164 | AQ37: 296.4561 | AR37: 289.53625 | AS37: =AVERAGE(AN37:AR37) -> 277.08052 | AT37: 277.08026 | AU37: =_xlfn.STDEV.S(AP37:AR37) -> 6.9198523 | AW37: =AD37-AT37 -> -46.330379 | AX37: =ABS(AW37)/AD37 -> 0.20078181
B38: M3 - Mod | C38: 56 | D38: =AVERAGE(116.5,116.2,116.4,116.3) -> 116.35 | E38: 101 | F38: =(D38/10)*(PI()/4)*((E38/10)^2) -> 932.17836 | G38: 1660.6 | H38: =G38/F38 -> 1.7814187 | I38: 0.080713111 | J38: =H38/(1+I38) -> 1.6483734 | K38: 2.5 | L38: =K38/J38-1 -> 0.51664666 | M38: =I38*(K38/L38) -> 0.39056244 | O38: 0.1 | P38: 200.01 | Q38: 242.95 | R38: 201.14 | S38: 218.09 | T38: 215.83 | V38: =(((($D38/10)/P38)*10000)^2)*(($H38*1000*(1+$O38)*(1-2*($O38)))/(1-$O38))/1000000 -> 589.43448 | X38: =(((($D38/10)/R38)*10000)^2)*(($H38*1000*(1+$O38)*(1-2*($O38)))/(1-$O38))/1000000 -> 582.83022 | Y38: =(((($D38/10)/S38)*10000)^2)*(($H38*1000*(1+$O38)*(1-2*($O38)))/(1-$O38))/1000000 -> 495.7554 | Z38: =(((($D38/10)/T38)*10000)^2)*(($H38*1000*(1+$O38)*(1-2*($O38)))/(1-$O38))/1000000 -> 506.19207 | AA38: 30 | AB38: =Q38+AA38 -> 272.95 | AC38: =_xlfn.STDEV.S(P38:T38) -> 17.366744 | AD38: =((((D38/10)/AB38)*10000)^2)*((H38*1000*(1+O38)*(1-2*(O38)))/(1-O38))/1000000 -> 316.4993 | AE38: =AD38 -> 316.4993 | AF38: =_xlfn.STDEV.S(V38,X38:Z38) -> 49.42422 | AH38: 0.0012500125 | AI38: 0.0012200122 | AJ38: 0.0012400124 | AK38: 0.0012400124 | AL38: 0.0012400124 | AM38: =AVERAGE(AH38:AL38) -> 0.0012380124 | AN38: 297.21661 | AO38: 344.91377 | AP38: 310.33618 | AQ38: 310.33618 | AR38: 310.33618 | AS38: =AVERAGE(AN38:AR38) -> 314.62778 | AT38: 305.52195 | AU38: =_xlfn.STDEV.S(AN38:AR38) -> 17.858078 | AW38: =AD38-AT38 -> 10.977352 | AX38: =ABS(AW38)/AD38 -> 0.034683654
B39: M1 - Est | C39: 25 | D39: =AVERAGE(116.3,116.7,116.5) -> 116.5 | E39: 101 | F39: =(D39/10)*(PI()/4)*((E39/10)^2) -> 933.38014 | G39: 1542.2 | H39: =G39/F39 -> 1.6522743 | I39: 0.11589041 | J39: =H39/(1+I39) -> 1.4806779 | K39: 2.5 | L39: =K39/J39-1 -> 0.68841581 | M39: =I39*(K39/L39) -> 0.42085906 | O39: 0.11 | P39: 527.71 | Q39: 461.04 | R39: 482.51 | S39: 500.59 | T39: 498.33 | V39: =(((($D39/10)/P39)*10000)^2)*(($H39*1000*(1+$O39)*(1-2*($O39)))/(1-$O39))/1000000 -> 78.337719 | W39: =(((($D39/10)/Q39)*10000)^2)*(($H39*1000*(1+$O39)*(1-2*($O39)))/(1-$O39))/1000000 -> 102.63237 | X39: =(((($D39/10)/R39)*10000)^2)*(($H39*1000*(1+$O39)*(1-2*($O39)))/(1-$O39))/1000000 -> 93.702016 | Y39: =(((($D39/10)/S39)*10000)^2)*(($H39*1000*(1+$O39)*(1-2*($O39)))/(1-$O39))/1000000 -> 87.055704 | Z39: =(((($D39/10)/T39)*10000)^2)*(($H39*1000*(1+$O39)*(1-2*($O39)))/(1-$O39))/1000000 -> 87.847115 | AA39: 0 | AB39: =AVERAGE(P39:T39) -> 494.036 | AC39: =_xlfn.STDEV.S(P39:T39) -> 24.581072 | AD39: =((((D39/10)/AB39)*10000)^2)*((H39*1000*(1+O39)*(1-2*(O39)))/(1-O39))/1000000 -> 89.380829 | AE39: =AD39 -> 89.380829 | AF39: =_xlfn.STDEV.S(V39:Z39) -> 8.9799518 | AH39: 0.0019200192 | AI39: 0.0018700187 | AJ39: 0.0018600186 | AK39: 0.001900019 | AL39: 0.0019300193 | AM39: =AVERAGE(AH39:AL39) -> 0.001896019 | AN39: 46.693929 | AO39: 53.606398 | AP39: 54.988892 | AQ39: 49.458917 | AR39: 45.311435 | AS39: =AVERAGE(AN39:AR39) -> 50.011914 | AT39: 50.011897 | AU39: =_xlfn.STDEV.S(AN39:AR39) -> 4.2160395 | AW39: =AD39-AT39 -> 39.368931 | AX39: =ABS(AW39)/AD39 -> 0.44046281
B40: M2 - Est | C40: 25 | D40: =AVERAGE(116.5,116.2,116.4,116.3) -> 116.35 | E40: 101 | F40: =(D40/10)*(PI()/4)*((E40/10)^2) -> 932.17836 | G40: 1576.4 | H40: =G40/F40 -> 1.6910927 | I40: 0.13460443 | J40: =H40/(1+I40) -> 1.490469 | K40: 2.5 | L40: =K40/J40-1 -> 0.67732443 | M40: =I40*(K40/L40) -> 0.49682405 | O40: 0.13 | P40: 597.77 | Q40: 474.6 | R40: 523.19 | S40: 461.04 | T40: 493.81 | V40: =(((($D40/10)/P40)*10000)^2)*(($H40*1000*(1+$O40)*(1-2*($O40)))/(1-$O40))/1000000 -> 61.577615 | W40: =(((($D40/10)/Q40)*10000)^2)*(($H40*1000*(1+$O40)*(1-2*($O40)))/(1-$O40))/1000000 -> 97.686743 | X40: =(((($D40/10)/R40)*10000)^2)*(($H40*1000*(1+$O40)*(1-2*($O40)))/(1-$O40))/1000000 -> 80.384484 | Y40: =(((($D40/10)/S40)*10000)^2)*(($H40*1000*(1+$O40)*(1-2*($O40)))/(1-$O40))/1000000 -> 103.51753 | Z40: =(((($D40/10)/T40)*10000)^2)*(($H40*1000*(1+$O40)*(1-2*($O40)))/(1-$O40))/1000000 -> 90.234234 | AA40: 0 | AB40: =AVERAGE(P40:T40) -> 510.082 | AC40: =_xlfn.STDEV.S(P40:T40) -> 54.290591 | AD40: =((((D40/10)/AB40)*10000)^2)*((H40*1000*(1+O40)*(1-2*(O40)))/(1-O40))/1000000 -> 84.568981 | AE40: =AD40 -> 84.568981 | AF40: =_xlfn.STDEV.S(V40:Z40) -> 16.485194 | AH40: 0.0018500185 | AI40: 0.0018500185 | AJ40: 0.0017400174 | AK40: 0.0018700187 | AL40: 0.0018700187 | AM40: =AVERAGE(AH40:AL40) -> 0.0018360184 | AN40: 56.115377 | AO40: 56.115377 | AP40: 71.361921 | AQ40: 53.343279 | AR40: 53.343279 | AS40: =AVERAGE(AN40:AR40) -> 58.055847 | AT40: 58.055829 | AU40: =_xlfn.STDEV.S(AN40:AR40) -> 7.5663572 | AW40: =AD40-AT40 -> 26.513152 | AX40: =ABS(AW40)/AD40 -> 0.31350918
B41: M3 - Est | C41: 25 | D41: =AVERAGE(116.3,116.7,116.5) -> 116.5 | E41: 101 | F41: =(D41/10)*(PI()/4)*((E41/10)^2) -> 933.38014 | G41: 1627.8 | H41: =G41/F41 -> 1.743984 | I41: 0.1402803 | J41: =H41/(1+I41) -> 1.5294345 | K41: 2.5 | L41: =K41/J41-1 -> 0.63459114 | M41: =I41*(K41/L41) -> 0.55264047 | O41: 0.16 | P41: 491.55 | Q41: 491.55 | R41: 517.54 | S41: 553.7 | T41: 586.47 | V41: =(((($D41/10)/P41)*10000)^2)*(($H41*1000*(1+$O41)*(1-2*($O41)))/(1-$O41))/1000000 -> 91.991257 | W41: =(((($D41/10)/Q41)*10000)^2)*(($H41*1000*(1+$O41)*(1-2*($O41)))/(1-$O41))/1000000 -> 91.991257 | X41: =(((($D41/10)/R41)*10000)^2)*(($H41*1000*(1+$O41)*(1-2*($O41)))/(1-$O41))/1000000 -> 82.983952 | Y41: =(((($D41/10)/S41)*10000)^2)*(($H41*1000*(1+$O41)*(1-2*($O41)))/(1-$O41))/1000000 -> 72.499149 | Z41: =(((($D41/10)/T41)*10000)^2)*(($H41*1000*(1+$O41)*(1-2*($O41)))/(1-$O41))/1000000 -> 64.623482 | AA41: -120 | AB41: =Q41+AA41 -> 371.55 | AC41: =_xlfn.STDEV.S(P41:T41) -> 41.369422 | AD41: =((((D41/10)/AB41)*10000)^2)*((H41*1000*(1+O41)*(1-2*(O41)))/(1-O41))/1000000 -> 161.00799 | AE41: =AD41 -> 161.00799 | AF41: =_xlfn.STDEV.S(V41:Z41) -> 12.10207 | AH41: 0.0014100141 | AI41: 0.001400014 | AJ41: 0.0013700137 | AK41: 0.0014200142 | AL41: 0.0015200152 | AM41: =AVERAGE(AH41:AL41) -> 0.0014240142 | AN41: 184.26622 | AO41: 191.18309 | AP41: 211.93369 | AQ41: 177.34936 | AR41: 108.1807 | AS41: =AVERAGE(AN41:AR41) -> 174.58261 | AT41: 174.58244 | AU41: =_xlfn.STDEV.S(AN41:AQ41) -> 14.942138 | AW41: =AD41-AT41 -> -13.57445 | AX41: =ABS(AW41)/AD41 -> 0.084309168
B42: M4 - Est | C42: 25 | D42: =AVERAGE(116.5,116.2,116.4,116.3) -> 116.35 | E42: 101 | F42: =(D42/10)*(PI()/4)*((E42/10)^2) -> 932.17836 | G42: 1661.2 | H42: =G42/F42 -> 1.7820624 | I42: 0.15156951 | J42: =H42/(1+I42) -> 1.5475075 | K42: 2.5 | L42: =K42/J42-1 -> 0.6155011 | M42: =I42*(K42/L42) -> 0.61563459 | O42: 0.22 | P42: 476.86 | Q42: 438.44 | R42: 414.71 | S42: 323.18 | T42: 392.11 | V42: =(((($D42/10)/P42)*10000)^2)*(($H42*1000*(1+$O42)*(1-2*($O42)))/(1-$O42))/1000000 -> 92.92384 | W42: =(((($D42/10)/Q42)*10000)^2)*(($H42*1000*(1+$O42)*(1-2*($O42)))/(1-$O42))/1000000 -> 109.92301 | X42: =(((($D42/10)/R42)*10000)^2)*(($H42*1000*(1+$O42)*(1-2*($O42)))/(1-$O42))/1000000 -> 122.86266 | Y42: =(((($D42/10)/S42)*10000)^2)*(($H42*1000*(1+$O42)*(1-2*($O42)))/(1-$O42))/1000000 -> 202.31123 | Z42: =(((($D42/10)/T42)*10000)^2)*(($H42*1000*(1+$O42)*(1-2*($O42)))/(1-$O42))/1000000 -> 137.43366 | AA42: 0 | AB42: =AVERAGE(P42:T42) -> 409.06 | AC42: =_xlfn.STDEV.S(P42:T42) -> 57.346804 | AD42: =((((D42/10)/AB42)*10000)^2)*((H42*1000*(1+O42)*(1-2*(O42)))/(1-O42))/1000000 -> 126.2801 | AE42: =AD42 -> 126.2801 | AF42: =_xlfn.STDEV.S(V42:X42,Z42) -> 18.936325 | AH42: 0.0017400174 | AI42: 0.0016400164 | AJ42: 0.0016200162 | AK42: 0.0016200162 | AL42: 0.0016400164 | AM42: =AVERAGE(AH42:AL42) -> 0.0016520165 | AN42: 70.371918 | AO42: 84.394703 | AP42: 87.19926 | AQ42: 87.19926 | AR42: 84.394703 | AS42: =AVERAGE(AN42:AR42) -> 82.711969 | AT42: 82.71195 | AU42: =_xlfn.STDEV.S(AN42:AR42) -> 7.0393823 | AW42: =AD42-AT42 -> 43.568147 | AX42: =ABS(AW42)/AD42 -> 0.34501199
B44: MEDICIÓN #4
B46: Datos Probetas | O46: Análisis Velocidad Onda P | AH46: Mod. E Pelotazo | AW46: Analisis Errores
B47: Probeta | C47: Energía | D47: Altura | E47: Diámetro | F47: Volumen | G47: Masa | H47: Densidad | I47: Humedad | J47: Den. Seca | K47: GS | L47: e | M47: Saturación | O47: Poisson | P47: TV1 | Q47: TV2 | R47: TV3 | S47: TV4 | T47: TV5 | AB47: TV prom | AD47: Mod E | AH47: TOF1 | AI47: TOF2 | AJ47: TOF3 | AK47: TOF4 | AL47: TOF5 | AM47: TOF Prom | AN47: E1 | AO47: E2 | AP47: E3 | AQ47: E4 | AR47: E5 | AS47: Mod E | AT47: Mod E | AW47: Diferencia | AX47: % Error
B48: - | C48: Golpes | D48: mm | E48: mm | F48: cm3 | G48: g | H48: g/cm3 | I48: % | J48: g/cm3 | K48: - | L48: - | M48: % | O48: - | P48: us | Q48: us | R48: us | S48: us | T48: us | AB48: us | AD48: Mpa | AH48: s | AI48: s | AJ48: s | AK48: s | AL48: s | AM48: s | AN48: Mpa | AO48: Mpa | AP48: Mpa | AQ48: Mpa | AR48: Mpa | AS48: Average | AT48: Mpa | AW48: Mpa | AX48: %
...

Sheet RAW_Ceramica_TOFvsOndaP (2)
B2: MEDICIÓN #1
B4: Datos Probetas | O4: Análisis Velocidad Onda P | AH4: Mod. E Pelotazo
B5: Probeta | C5: Energía | D5: Altura | E5: Diámetro | F5: Volumen | G5: Masa | H5: Densidad | I5: Humedad | J5: Den. Seca | K5: GS | L5: e | M5: Saturación | O5: Poisson | P5: TV1 | Q5: TV2 | R5: TV3 | S5: TV4 | T5: TV5 | AB5: TV prom | AD5: Mod E | AH5: TOF1 | AI5: TOF2 | AJ5: TOF3 | AK5: TOF4 | AL5: TOF5 | AM5: TOF Prom | AN5: E1 | AO5: E2 | AP5: E3 | AQ5: E4 | AR5: E5 | AT5: Mod E
B6: - | C6: Golpes | D6: mm | E6: mm | F6: cm3 | G6: g | H6: g/cm3 | I6: % | J6: g/cm3 | K6: - | L6: - | M6: % | O6: - | P6: us | Q6: us | R6: us | S6: us | T6: us | AB6: us | AD6: Mpa | AH6: s | AI6: s | AJ6: s | AK6: s | AL6: s | AM6: s | AN6: Mpa | AO6: Mpa | AP6: Mpa | AQ6: Mpa | AR6: Mpa | AT6: Mpa
B7: Masa 1 | C7: 25 | D7: 116.5 | E7: 102 | F7: =(D7/10)*(PI()/4)*((E7/10)^2) -> 951.95441 | G7: 1931.2 | H7: =G7/F7 -> 2.0286686 | I7: 0.13873393 | J7: =H7/(1+I7) -> 1.7815124 | K7: 2.5 | L7: =K7/J7-1 -> 0.40330208 | M7: =I7*(K7/L7) -> 0.85998771
B8: Masa 2 | C8: 25 | D8: 117.7 | E8: 101.8 | F8: =(D8/10)*(PI()/4)*((E8/10)^2) -> 957.99204 | G8: 1925 | H8: =G8/F8 -> 2.0094113 | I8: 0.1654157 | J8: =H8/(1+I8) -> 1.7242013 | K8: 2.5 | L8: =K8/J8-1 -> 0.44994671 | M8: =I8*(K8/L8) -> 0.91908497
B9: Masa 3 | C9: 25 | D9: 116.9 | E9: 101.1 | F9: =(D9/10)*(PI()/4)*((E9/10)^2) -> 938.44042 | G9: 1837 | H9: =G9/F9 -> 1.9575031 | I9: 0.1839677 | J9: =H9/(1+I9) -> 1.6533416 | K9: 2.5 | L9: =K9/J9-1 -> 0.5120892 | M9: =I9*(K9/L9) -> 0.89812333
B10: Masa 4 | C10: 25 | D10: =AVERAGE(D9,D12) -> 116.69 | E10: 102.2 | F10: =(D10/10)*(PI()/4)*((E10/10)^2) -> 957.24986 | G10: 1795.5 | H10: =G10/F10 -> 1.8756858 | I10: 0.10371452 | J10: =H10/(1+I10) -> 1.6994302 | K10: 2.5 | L10: =K10/J10-1 -> 0.47108128 | M10: =I10*(K10/L10) -> 0.55040674
B11: Masa 5 | C11: 25 | D11: 118.3 | E11: 101.5 | F11: =(D11/10)*(PI()/4)*((E11/10)^2) -> 957.20886 | G11: 1943.5 | H11: =G11/F11 -> 2.0303824 | I11: 0.15280665 | J11: =H11/(1+I11) -> 1.7612514 | K11: 2.5 | L11: =K11/J11-1 -> 0.41944526 | M11: =I11*(K11/L11) -> 0.91076636
B12: Masa 6 | C12: 25 | D12: 116.48 | E12: 101.8 | F12: =(D12/10)*(PI()/4)*((E12/10)^2) -> 948.06213 | G12: 1888.5 | H12: =G12/F12 -> 1.9919581 | I12: 0.17336269 | J12: =H12/(1+I12) -> 1.6976491 | K12: 2.5 | L12: =K12/J12-1 -> 0.47262474 | M12: =I12*(K12/L12) -> 0.9170208
B13: Masa 7 | C13: 25 | D13: 115.88 | E13: 101.5 | F13: =(D13/10)*(PI()/4)*((E13/10)^2) -> 937.62775 | G13: 1918.5 | H13: =G13/F13 -> 2.0461212 | I13: 0.19547775 | J13: =H13/(1+I13) -> 1.711551 | K13: 2.5 | L13: =K13/J13-1 -> 0.46066343 | M13: =I13*(K13/L13) -> 1.0608491
B15: MEDICIÓN #2
B17: Datos Probetas | O17: Análisis Velocidad Onda P | AH17: Mod. E Pelotazo
B18: Probeta | C18: Energía | D18: Altura | E18: Diámetro | F18: Volumen | G18: Masa | H18: Densidad | I18: Humedad | J18: Den. Seca | K18: GS | L18: e | M18: Saturación | O18: Poisson | P18: TV1 | Q18: TV2 | R18: TV3 | S18: TV4 | T18: TV5 | AB18: TV prom | AD18: Mod E | AH18: TOF1 | AI18: TOF2 | AJ18: TOF3 | AK18: TOF4 | AL18: TOF5 | AM18: TOF Prom | AN18: E1 | AO18: E2 | AP18: E3 | AQ18: E4 | AR18: E5 | AT18: Mod E
B19: - | C19: Golpes | D19: mm | E19: mm | F19: cm3 | G19: g | H19: g/cm3 | I19: % | J19: g/cm3 | K19: - | L19: - | M19: % | O19: - | P19: us | Q19: us | R19: us | S19: us | T19: us | AB19: us | AD19: Mpa | AH19: s | AI19: s | AJ19: s | AK19: s | AL19: s | AM19: s | AN19: Mpa | AO19: Mpa | AP19: Mpa | AQ19: Mpa | AR19: Mpa | AT19: Mpa
B20: Masa 1 | C20: 25 | D20: 116.6 | E20: 102.7 | F20: =(D20/10)*(PI()/4)*((E20/10)^2) -> 965.89367 | G20: 1886.25 | H20: =G20/F20 -> 1.9528547 | I20: 0.20908379 | J20: =H20/(1+I20) -> 1.6151525 | K20: 2.5 | L20: =K20/J20-1 -> 0.54784145 | M20: =I20*(K20/L20) -> 0.95412545
B21: Masa 2 | C21: 25 | D21: 117.7 | E21: 101.9 | F21: =(D21/10)*(PI()/4)*((E21/10)^2) -> 959.87507 | G21: 1876.16 | H21: =G21/F21 -> 1.9545877 | I21: 0.17261905 | J21: =H21/(1+I21) -> 1.6668565 | K21: 2.5 | L21: =K21/J21-1 -> 0.49982916 | M21: =I21*(K21/L21) -> 0.86339024
B22: Masa 3 | C22: 25 | D22: 116.3 | E22: 101.2 | F22: =(D22/10)*(PI()/4)*((E22/10)^2) -> 935.47163 | G22: 1771.46 | H22: =G22/F22 -> 1.8936544 | I22: 0.15281757 | J22: =H22/(1+I22) -> 1.6426315 | K22: 2.5 | L22: =K22/J22-1 -> 0.52194819 | M22: =I22*(K22/L22) -> 0.73195758
B23: Masa 4 | C23: 25 | D23: 119 | E23: 102 | F23: =(D23/10)*(PI()/4)*((E23/10)^2) -> 972.38262 | G23: 1591.26 | H23: =G23/F23 -> 1.6364546 | I23: 0.098525989 | J23: =H23/(1+I23) -> 1.4896822 | K23: 2.5 | L23: =K23/J23-1 -> 0.67821031 | M23: =I23*(K23/L23) -> 0.36318376
B24: Masa 1 | C24: 56 | D24: 119.6 | E24: 101.8 | F24: =(D24/10)*(PI()/4)*((E24/10)^2) -> 973.45665 | G24: 1936.8 | H24: =G24/F24 -> 1.9896109 | I24: 0.17013766 | J24: =H24/(1+I24) -> 1.7003221 | K24: 2.5 | L24: =K24/J24-1 -> 0.47030965 | M24: =I24*(K24/L24) -> 0.90439173
B25: Masa 2 | C25: 56 | D25: 118 | E25: 102.3 | F25: =(D25/10)*(PI()/4)*((E25/10)^2) -> 969.89151 | G25: 1740.16 | H25: =G25/F25 -> 1.7941801 | I25: 0.11027138 | J25: =H25/(1+I25) -> 1.6159833 | K25: 2.5 | L25: =K25/J25-1 -> 0.54704565 | M25: =I25*(K25/L25) -> 0.5039405
B26: Masa 3 | C26: 56 | D26: 116.8 | E26: 101.9 | F26: =(D26/10)*(PI()/4)*((E26/10)^2) -> 952.53533 | G26: 1903.78 | H26: =G26/F26 -> 1.998645 | I26: 0.18211382 | J26: =H26/(1+I26) -> 1.6907382 | K26: 2.5 | L26: =K26/J26-1 -> 0.47864404 | M26: =I26*(K26/L26) -> 0.95119654
B27: Masa 4 | C27: 56 | D27: 118 | E27: 101.7 | F27: =(D27/10)*(PI()/4)*((E27/10)^2) -> 958.54784 | G27: 1839.59 | H27: =G27/F27 -> 1.9191426 | I27: 0.14310051 | J27: =H27/(1+I27) -> 1.6788923 | K27: 2.5 | L27: =K27/J27-1 -> 0.48907709 | M27: =I27*(K27/L27) -> 0.73148239
B28: Masa 5 | C28: 56 | D28: 117.8 | E28: 102 | F28: =(D28/10)*(PI()/4)*((E28/10)^2) -> 962.57708 | G28: 1878.62 | H28: =G28/F28 -> 1.9516567 | I28: 0.21071013 | J28: =H28/(1+I28) -> 1.6119934 | K28: 2.5 | L28: =K28/J28-1 -> 0.55087487 | M28: =I28*(K28/L28) -> 0.95625223
B30: MEDICIÓN #3
B32: Datos Probetas | O32: Análisis Velocidad Onda P | AH32: Mod. E Pelotazo | AW32: Analisis Errores
B33: Probeta | C33: Energía | D33: Altura | E33: Diámetro | F33: Volumen | G33: Masa | H33: Densidad | I33: Humedad | J33: Den. Seca | K33: GS | L33: e | M33: Saturación | O33: Poisson | P33: TV1 | Q33: TV2 | R33: TV3 | S33: TV4 | T33: TV5 | V33: E1 | W33: E2 | X33: E3 | Y33: E4 | Z33: E5 | AA33: Ajuste | AB33: TV prom | AC33: desvest TV | AD33: Mod E | AE33: E prom | AF33: desvest E | AH33: TOF1 | AI33: TOF2 | AJ33: TOF3 | AK33: TOF4 | AL33: TOF5 | AM33: TOF Prom | AN33: E1 | AO33: E2 | AP33: E3 | AQ33: E4 | AR33: E5 | AS33: Mod E | AT33: Mod E | AU33: desvest E | AW33: Diferencia | AX33: % Error
B34: - | C34: Golpes | D34: mm | E34: mm | F34: cm3 | G34: g | H34: g/cm3 | I34: % | J34: g/cm3 | K34: - | L34: - | M34: % | O34: - | P34: us | Q34: us | R34: us | S34: us | T34: us | AB34: us | AD34: Mpa | AH34: s | AI34: s | AJ34: s | AK34: s | AL34: s | AM34: s | AN34: Mpa | AO34: Mpa | AP34: Mpa | AQ34: Mpa | AR34: Mpa | AS34: Average | AT34: Mpa | AW34: Mpa | AX34: %
B35: M1 - Mod | C35: 25 | D35: =AVERAGE(116.3,117.4,117.4) -> 117.03333 | E35: 101 | F35: =(D35/10)*(PI()/4)*((E35/10)^2) -> 937.65312 | G35: 1739.2 | H35: =G35/F35 -> 1.8548437 | I35: 0.11843409 | J35: =H35/(1+I35) -> 1.6584292 | K35: 2.5 | L35: =K35/J35-1 -> 0.50745058 | M35: =I35*(K35/L35) -> 0.583476 | O35: 0.2 | P35: 246.34 | Q35: 244.08 | R35: 254.25 | S35: 223.74 | T35: 256.51 | V35: =(((($D35/10)/P35)*10000)^2)*(($H35*1000*(1+$O35)*(1-2*($O35)))/(1-$O35))/1000000 -> 376.78977 | W35: =(((($D35/10)/Q35)*10000)^2)*(($H35*1000*(1+$O35)*(1-2*($O35)))/(1-$O35))/1000000 -> 383.79967 | X35: =(((($D35/10)/R35)*10000)^2)*(($H35*1000*(1+$O35)*(1-2*($O35)))/(1-$O35))/1000000 -> 353.70977 | Z35: =(((($D35/10)/T35)*10000)^2)*(($H35*1000*(1+$O35)*(1-2*($O35)))/(1-$O35))/1000000 -> 347.50446 | AA35: 0 | AB35: =AVERAGE(T35)+AA35 -> 256.51 | AC35: =_xlfn.STDEV.S(P35:T35) -> 12.96795 | AD35: =((((D35/10)/AB35)*10000)^2)*((H35*1000*(1+O35)*(1-2*(O35)))/(1-O35))/1000000 -> 347.50446 | AE35: =AD35 -> 347.50446 | AF35: =_xlfn.STDEV.S(V35:Z35) -> 17.561095 | AH35: 0.0013500135 | AI35: 0.0013200132 | AJ35: 0.0013700137 | AK35: 0.0013500135 | AL35: 0.0013700137 | AM35: =AVERAGE(AH35:AL35) -> 0.0013520135 | AN35: 224.27854 | AO35: 245.02019 | AP35: 210.45078 | AQ35: 224.27854 | AR35: 210.45078 | AS35: =AVERAGE(AN35:AR35) -> 222.89577 | AT35: 222.89555 | AU35: =_xlfn.STDEV.S(AN35:AR35) -> 14.169241 | AW35: =AD35-AT35 -> 124.60891 | AX35: =ABS(AW35)/AD35 -> 0.35858218
B36: M1 - Mod | C36: 56 | D36: =AVERAGE(116.5,116.2,116.4,116.3) -> 116.35 | E36: 101 | F36: =(D36/10)*(PI()/4)*((E36/10)^2) -> 932.17836 | G36: 1838.2 | H36: =G36/F36 -> 1.9719402 | I36: 0.11805226 | J36: =H36/(1+I36) -> 1.7637281 | K36: 2.5 | L36: =K36/J36-1 -> 0.41745202 | M36: =I36*(K36/L36) -> 0.70698099 | O36: 0.34 | P36: 308.49 | Q36: 341.26 | R36: 341.26 | S36: 359.34 | T36: 368.38 | V36: =(((($D36/10)/P36)*10000)^2)*(($H36*1000*(1+$O36)*(1-2*($O36)))/(1-$O36))/1000000 -> 182.24481 | W36: =(((($D36/10)/Q36)*10000)^2)*(($H36*1000*(1+$O36)*(1-2*($O36)))/(1-$O36))/1000000 -> 148.92465 | X36: =(((($D36/10)/R36)*10000)^2)*(($H36*1000*(1+$O36)*(1-2*($O36)))/(1-$O36))/1000000 -> 148.92465 | Y36: =(((($D36/10)/S36)*10000)^2)*(($H36*1000*(1+$O36)*(1-2*($O36)))/(1-$O36))/1000000 -> 134.31553 | Z36: =(((($D36/10)/T36)*10000)^2)*(($H36*1000*(1+$O36)*(1-2*($O36)))/(1-$O36))/1000000 -> 127.80424 | AA36: 0 | AB36: =P36 -> 308.49 | AC36: =_xlfn.STDEV.S(P36:T36) -> 22.942061 | AD36: =((((D36/10)/AB36)*10000)^2)*((H36*1000*(1+O36)*(1-2*(O36)))/(1-O36))/1000000 -> 182.24481 | AE36: =AD36 -> 182.24481 | AF36: =_xlfn.STDEV.S(V36:Z36) -> 21.027186 | AH36: 0.0013900139 | AI36: 0.0012600126 | AJ36: 0.0013400134 | AK36: 0.0013100131 | AL36: 0.0012900129 | AM36: =AVERAGE(AH36:AL36) -> 0.0013180132 | AN36: 180.60107 | AO36: 222.13458 | AP36: 242.90134 | AQ36: 256.74584 | AR36: 187.52332 | AS36: =AVERAGE(AN36:AR36) -> 217.98123 | AT36: 221.83875 | AU36: =_xlfn.STDEV.S(AN36:AP36) -> 31.721744 | AW36: =AD36-AT36 -> -39.593931 | AX36: =ABS(AW36)/AD36 -> 0.21725683
B37: M2 - Mod | C37: 56 | D37: =AVERAGE(116.3,116.7,116.5) -> 116.5 | E37: 101 | F37: =(D37/10)*(PI()/4)*((E37/10)^2) -> 933.38014 | G37: 1722 | H37: =G37/F37 -> 1.8449075 | I37: 0.096678108 | J37: =H37/(1+I37) -> 1.6822689 | K37: 2.5 | L37: =K37/J37-1 -> 0.48608821 | M37: =I37*(K37/L37) -> 0.49722512 | O37: 0.12 | P37: 243.97907 | Q37: 227.13 | R37: 195.49 | S37: 202.27 | T37: 235.04 | V37: =(((($D37/10)/P37)*10000)^2)*(($H37*1000*(1+$O37)*(1-2*($O37)))/(1-$O37))/1000000 -> 406.88367 | W37: =(((($D37/10)/Q37)*10000)^2)*(($H37*1000*(1+$O37)*(1-2*($O37)))/(1-$O37))/1000000 -> 469.49004 | Y37: =(((($D37/10)/S37)*10000)^2)*(($H37*1000*(1+$O37)*(1-2*($O37)))/(1-$O37))/1000000 -> 591.98736 | Z37: =(((($D37/10)/T37)*10000)^2)*(($H37*1000*(1+$O37)*(1-2*($O37)))/(1-$O37))/1000000 -> 438.42149 | AA37: 0 | AB37: =P37+AA37 -> 243.97907 | AC37: =_xlfn.STDEV.S(P37:T37) -> 21.000422 | AD37: =((((D37/10)/AB37)*10000)^2)*((H37*1000*(1+O37)*(1-2*(O37)))/(1-O37))/1000000 -> 406.88367 | AE37: =AD37 -> 406.88367 | AF37: =_xlfn.STDEV.S(V37:W37,Z37) -> 31.30348 | AH37: 0.0013300133 | AI37: 0.0012800128 | AJ37: 0.0012700127 | AK37: 0.0012500125 | AL37: 0.0012600126 | AM37: =AVERAGE(AH37:AL37) -> 0.0012780128 | AN37: 241.09728 | AO37: 275.69655 | AP37: 282.6164 | AQ37: 296.4561 | AR37: 289.53625 | AS37: =AVERAGE(AN37:AR37) -> 277.08052 | AT37: 277.08026 | AU37: =_xlfn.STDEV.S(AP37:AR37) -> 6.9198523 | AW37: =AD37-AT37 -> 129.80341 | AX37: =ABS(AW37)/AD37 -> 0.31901847
B38: M3 - Mod | C38: 56 | D38: =AVERAGE(116.5,116.2,116.4,116.3) -> 116.35 | E38: 101 | F38: =(D38/10)*(PI()/4)*((E38/10)^2) -> 932.17836 | G38: 1660.6 | H38: =G38/F38 -> 1.7814187 | I38: 0.080713111 | J38: =H38/(1+I38) -> 1.6483734 | K38: 2.5 | L38: =K38/J38-1 -> 0.51664666 | M38: =I38*(K38/L38) -> 0.39056244 | O38: 0.1 | P38: 200.01 | Q38: 242.95 | R38: 201.14 | S38: 218.09 | T38: 215.83 | V38: =(((($D38/10)/P38)*10000)^2)*(($H38*1000*(1+$O38)*(1-2*($O38)))/(1-$O38))/1000000 -> 589.43448 | X38: =(((($D38/10)/R38)*10000)^2)*(($H38*1000*(1+$O38)*(1-2*($O38)))/(1-$O38))/1000000 -> 582.83022 | Y38: =(((($D38/10)/S38)*10000)^2)*(($H38*1000*(1+$O38)*(1-2*($O38)))/(1-$O38))/1000000 -> 495.7554 | Z38: =(((($D38/10)/T38)*10000)^2)*(($H38*1000*(1+$O38)*(1-2*($O38)))/(1-$O38))/1000000 -> 506.19207 | AA38: 0 | AB38: =Q38+AA38 -> 242.95 | AC38: =_xlfn.STDEV.S(P38:T38) -> 17.366744 | AD38: =((((D38/10)/AB38)*10000)^2)*((H38*1000*(1+O38)*(1-2*(O38)))/(1-O38))/1000000 -> 399.4893 | AE38: =AD38 -> 399.4893 | AF38: =_xlfn.STDEV.S(V38,X38:Z38) -> 49.42422 | AH38: 0.0012500125 | AI38: 0.0012200122 | AJ38: 0.0012400124 | AK38: 0.0012400124 | AL38: 0.0012400124 | AM38: =AVERAGE(AH38:AL38) -> 0.0012380124 | AN38: 297.21661 | AO38: 344.91377 | AP38: 310.33618 | AQ38: 310.33618 | AR38: 310.33618 | AS38: =AVERAGE(AN38:AR38) -> 314.62778 | AT38: 305.52195 | AU38: =_xlfn.STDEV.S(AN38:AR38) -> 17.858078 | AW38: =AD38-AT38 -> 93.967346 | AX38: =ABS(AW38)/AD38 -> 0.23521868
B39: M1 - Est | C39: 25 | D39: =AVERAGE(116.3,116.7,116.5) -> 116.5 | E39: 101 | F39: =(D39/10)*(PI()/4)*((E39/10)^2) -> 933.38014 | G39: 1542.2 | H39: =G39/F39 -> 1.6522743 | I39: 0.11589041 | J39: =H39/(1+I39) -> 1.4806779 | K39: 2.5 | L39: =K39/J39-1 -> 0.68841581 | M39: =I39*(K39/L39) -> 0.42085906 | O39: 0.11 | P39: 527.71 | Q39: 461.04 | R39: 482.51 | S39: 500.59 | T39: 498.33 | V39: =(((($D39/10)/P39)*10000)^2)*(($H39*1000*(1+$O39)*(1-2*($O39)))/(1-$O39))/1000000 -> 78.337719 | W39: =(((($D39/10)/Q39)*10000)^2)*(($H39*1000*(1+$O39)*(1-2*($O39)))/(1-$O39))/1000000 -> 102.63237 | X39: =(((($D39/10)/R39)*10000)^2)*(($H39*1000*(1+$O39)*(1-2*($O39)))/(1-$O39))/1000000 -> 93.702016 | Y39: =(((($D39/10)/S39)*10000)^2)*(($H39*1000*(1+$O39)*(1-2*($O39)))/(1-$O39))/1000000 -> 87.055704 | Z39: =(((($D39/10)/T39)*10000)^2)*(($H39*1000*(1+$O39)*(1-2*($O39)))/(1-$O39))/1000000 -> 87.847115 | AA39: 0 | AB39: =AVERAGE(P39:T39) -> 494.036 | AC39: =_xlfn.STDEV.S(P39:T39) -> 24.581072 | AD39: =((((D39/10)/AB39)*10000)^2)*((H39*1000*(1+O39)*(1-2*(O39)))/(1-O39))/1000000 -> 89.380829 | AE39: =AD39 -> 89.380829 | AF39: =_xlfn.STDEV.S(V39:Z39) -> 8.9799518 | AH39: 0.0019200192 | AI39: 0.0018700187 | AJ39: 0.0018600186 | AK39: 0.001900019 | AL39: 0.0019300193 | AM39: =AVERAGE(AH39:AL39) -> 0.001896019 | AN39: 46.693929 | AO39: 53.606398 | AP39: 54.988892 | AQ39: 49.458917 | AR39: 45.311435 | AS39: =AVERAGE(AN39:AR39) -> 50.011914 | AT39: 50.011897 | AU39: =_xlfn.STDEV.S(AN39:AR39) -> 4.2160395 | AW39: =AD39-AT39 -> 39.368931 | AX39: =ABS(AW39)/AD39 -> 0.44046281
